<?xml version="1.0"?>
<robot name="two_dof_arm">

  <!-- Base link -->
  <link name="base_link">
    <inertial>
      <origin xyz="0 0 0" rpy="0 0 0"/>
      <mass value="1.0"/>
      <inertia ixx="0.01" ixy="0.0" ixz="0.0"
               iyy="0.01" iyz="0.0"
               izz="0.01"/>
    </inertial>

    <visual>
      <origin xyz="0 0 0.1" rpy="0 0 0"/>
      <geometry>
        <box size="0.2 0.2 0.2"/>
      </geometry>
    </visual>

    <collision>
      <origin xyz="0 0 0.1" rpy="0 0 0"/>
      <geometry>
        <box size="0.2 0.2 0.2"/>
      </geometry>
    </collision>
  </link>

  <!-- Link 1 -->
  <link name="link1">
    <inertial>
      <origin xyz="0.0 0 0.15" rpy="0 0 0"/>
      <mass value="0.5"/>
      <inertia ixx="0.005" ixy="0.0" ixz="0.0"
               iyy="0.005" iyz="0.0"
               izz="0.005"/>
    </inertial>

    <visual>
      <origin xyz="0.0 0 0.15" rpy="0 0 0"/>
      <geometry>
        <cylinder radius="0.03" length="0.3"/>
      </geometry>
    </visual>

    <collision>
      <origin xyz="0.0 0 0.15" rpy="0 0 0"/>
      <geometry>
        <cylinder radius="0.03" length="0.3"/>
      </geometry>
    </collision>
  </link>

  <joint name="joint1" type="revolute">
    <parent link="base_link"/>
    <child link="link1"/>
    <origin xyz="0 0 0.2" rpy="0 0 0"/>
    <axis xyz="0 1 0"/>
    <limit lower="-3.14" upper="3.14" effort="10" velocity="3"/>
  </joint>

  <!-- Link 2 -->
  <link name="link2">
    <inertial>
      <origin xyz="0.0 0 0.15" rpy="0 0 0"/>
      <mass value="0.3"/>
      <inertia ixx="0.003" ixy="0.0" ixz="0.0"
               iyy="0.003" iyz="0.0"
               izz="0.003"/>
    </inertial>

    <visual>
      <origin xyz="0.0 0 0.15" rpy="0 0 0"/>
      <geometry>
        <cylinder radius="0.025" length="0.3"/>
      </geometry>
    </visual>

    <collision>
      <origin xyz="0.0 0 0.15" rpy="0 0 0"/>
      <geometry>
        <cylinder radius="0.025" length="0.3"/>
      </geometry>
    </collision>
  </link>

  <joint name="joint2" type="revolute">
    <parent link="link1"/>
    <child link="link2"/>
    <origin xyz="0.0 0 0.3" rpy="0 0 0"/>
    <axis xyz="0 1 0"/>
    <limit lower="-2.0" upper="2.0" effort="10" velocity="3"/>
  </joint>

  <!-- ros2_control -->
  <ros2_control name="GazeboSystem" type="system">
    <hardware>
      <plugin>gazebo_ros2_control/GazeboSystem</plugin>
    </hardware>

    <joint name="joint1">
      <command_interface name="position"/>
      <state_interface name="position"/>
      <state_interface name="velocity"/>
    </joint>

    <joint name="joint2">
      <command_interface name="position"/>
      <state_interface name="position"/>
      <state_interface name="velocity"/>
    </joint>
  </ros2_control>

  <!-- Gazebo ros2_control plugin -->
  <gazebo>
    <plugin name="gazebo_ros2_control" filename="libgazebo_ros2_control.so">
      <parameters>
        /home/sylle/MAS_ws_public/install/two_dof_arm/share/two_dof_arm/config/controllers.yaml
      </parameters>
    </plugin>
  </gazebo>

</robot>
